<?xml version="1.0"?>
<robot name="aruco" xmlns:xacro="http://ros.org/wiki/xacro">

    <!-- Parâmetros -->
    <xacro:property name="cubo_mass" value="2" />  <!-- Massa do cubo -->
    <link name="world"/>
    <!-- Link do cubo -->
    <link name="cubo_link">
    <visual>
        <geometry>
        <mesh filename="package://smartfactory_description/meshes/aruco.dae"  scale="1 1 1"/>
        </geometry>
    </visual>

    <collision>
        <geometry>
        <box size="0.25 0.25 0.1"/>
        </geometry>
    </collision>

    <inertial>
        <mass value="${cubo_mass}"/>
        <inertia ixx="0.1" ixy="0.0" ixz="0.0" iyy="0.1" iyz="0.0" izz="0.1"/>
    </inertial>

    <!-- Propriedades de atrito e colisão para evitar quedas -->
        <surface>
            <friction>
                <ode>
                    <mu>5.0</mu>   <!-- Aumenta o atrito para evitar que ele escorregue -->
                    <mu2>5.0</mu2>
                </ode>
            </friction>
            <bounce>
                <restitution_coefficient>0.0</restitution_coefficient>  <!-- Evitar que ele "quique" -->
            </bounce>
        </surface>

    </link>
    <gazebo reference="cubo_link">
        <gravity>true</gravity> <!-- Ativa a gravidade -->
        <!-- <material>Gazebo/White</material> -->
    </gazebo>

    <!-- Joint fixa o cubo no ambiente -->
    <joint name="cubo_fixed_joint" type="floating">
    <!-- <origin xyz="1.0 2.0 0.5" rpy="0 0 0"/>  -->
    <parent link="world"/>
    <child link="cubo_link"/>
    </joint>

</robot>
